<?xml version="1.0" ?>
<robot name="raider">


  <link name="base_link"/>
  <joint name="base_to_hip_joint" type="fixed">
    <parent link="base_link"/>
    <child link="hip"/>
    <origin xyz="0 0 0.256"/>
  </joint>

  <link name="hip">
    <collision>
      <origin rpy="0 0 0" xyz="0 0 0"/>
      <geometry>
        <mesh filename="package://raider_description/meshes/Hip.stl" scale="1 1 1"/>
      </geometry>
    </collision>
    <visual>
      <origin rpy="0 0 0" xyz="0 0 0"/>
      <geometry>
        <mesh filename="package://raider_description/meshes/Hip.dae" scale="1 1 1"/>
      </geometry>
    </visual>
    <inertial>
        <origin xyz="0.0000122 -0.0121975 0.0013754" rpy="0 0 0"/>
      <mass value="0.354"/>
        <inertia ixx="2.399113558e-1" ixy="7.449718907e-4" ixz="3.800877e-4" iyy="2.74636168e-1" iyz="4.409017312e-4" izz="4.348051245e-1"/>
    </inertial>
  </link>

  <joint name="middle_hip_twist" type="revolute">
   <dynamics damping="0.2" friction="1"/>
   <limit upper="2.618" lower="-2.618" velocity="5.6" effort="3"/>
    <parent link="hip"/>
    <child link="chest"/>
    <origin xyz="0 0.01068 0.0558014"/>
    <axis xyz="0 0 1"/>
  </joint>

  <link name="chest">
    <collision>
      <origin rpy="0 0 0" xyz="0 0 0"/>
      <geometry>
        <mesh filename="package://raider_description/meshes/Chest.stl" scale="1 1 1"/>
      </geometry>
    </collision>
    <visual>
      <origin rpy="0 0 0" xyz="0 0 0"/>
      <geometry>
        <mesh filename="package://raider_description/meshes/Chest.dae" scale="1 1 1"/>
      </geometry>
    </visual>
    <inertial>
        <origin xyz="-0.00022088 -0.01276272 -0.00348415" rpy="0 0 0"/>
      <mass value="0.4759"/>
        <inertia ixx="4.223702652e-1" ixy="-3.301078629e-3" ixz="2.090821448e-3" iyy="6.174246752e-1" iyz="-1.577048904e-2" izz="7.086345078e-1"/>
    </inertial>
  </link>

  <joint name="chest_ultrasonic_joint" type="fixed">
    <parent link="chest"/>
    <child link="ultrasonic"/>
    <origin xyz="0.00245169 0.021 -0.00253035" rpy="0 0 1.570796327"/>
  </joint>

  <link name="ultrasonic">
    <collision>
      <origin rpy="0 0 0" xyz="0 0 0"/>
      <geometry>
        <mesh filename="package://raider_description/meshes/Ultrasonic.stl" scale="1 1 1"/>
      </geometry>
    </collision>
    <visual>
      <origin rpy="0 0 0" xyz="0 0 0"/>
      <geometry>
        <mesh filename="package://raider_description/meshes/Ultrasonic.dae" scale="1 1 1"/>
      </geometry>
    </visual>
    <inertial>
        <origin xyz="0.00247185 -0.00004761 -0.00235810" rpy="0 0 0"/>
      <mass value="0.01"/>
        <inertia ixx="2.139474989e-3" ixy="0" ixz="4.850827647e-6" iyy="4.619602422e-4" iyz="1.741724034e-8" izz="2.087809396e-3"/>
    </inertial>
  </link>

  <joint name="neck" type="revolute">
    <dynamics damping="0.2" friction="1"/>
    <limit effort="3" lower="-1" upper="0" velocity="5.6"/>
    <parent link="chest"/>
    <child link="head"/>
    <origin xyz="0.00140647 0.00829226 0.0295842"/>
    <axis xyz="1 0 0"/>
  </joint>

  <link name="head">
    <collision>
      <origin rpy="0 0 0" xyz="0 0 0"/>
      <geometry>
        <mesh filename="package://raider_description/meshes/Head.stl" scale="1 1 1"/>
      </geometry>
    </collision>
    <visual>
      <origin rpy="0 0 0" xyz="0 0 0"/>
      <geometry>
        <mesh filename="package://raider_description/meshes/Head.dae" scale="1 1 1"/>
      </geometry>
    </visual>
    <inertial>
        <origin xyz="-0.00138420 -0.01315501 0.02437730" rpy="0 0 0"/>
      <mass value="0.0483"/>
        <inertia ixx="2.578648133e-2" ixy="-8.977484979e-5" ixz="5.527300267e-5" iyy="1.868986014e-2" iyz="6.731484019e-4" izz="2.924100479e-2"/>
    </inertial>
  </link>

  <joint name="head_lifecam_joint" type="fixed">
    <parent link="head"/>
    <child link="lifecam"/>
    <origin xyz="-0.00139132 0.01 0.0277925" rpy="0 0 1.570796327"/>
  </joint>

  <link name="lifecam">
    <collision>
      <origin rpy="0 0 0" xyz="0 0 0"/>
      <geometry>
        <mesh filename="package://raider_description/meshes/Lifecam.stl" scale="1 1 1"/>
      </geometry>
    </collision>
    <visual>
      <origin rpy="0 0 0" xyz="0 0 0"/>
      <geometry>
        <mesh filename="package://raider_description/meshes/Lifecam.dae" scale="1 1 1"/>
      </geometry>
    </visual>
    <inertial>
        <origin xyz="-0.00908352 0.00000824 0.00014719" rpy="0 0 0"/>
      <mass value="0.0953"/>
        <inertia ixx="3.256564677e-3" ixy="0" ixz="0" iyy="6.165946502e-3" iyz="0" izz="6.494934623e-3"/>
    </inertial>
  </link>

  <joint name="left_shoulder_swing" type="revolute">
    <dynamics damping="0.2" friction="1"/>
    <limit effort="3" lower="-2.618" upper="2.618" velocity="5.6"/>
    <parent link="chest"/>
    <child link="left_shoulder"/>
    <origin xyz="-0.0748183 -0.00030104 0.0092405"/>
    <axis xyz="1 0 0"/>
  </joint>

  <link name="left_shoulder">
    <collision>
      <origin rpy="0 0 0" xyz="0 0 0"/>
      <geometry>
        <mesh filename="package://raider_description/meshes/Left_shoulder.stl" scale="1 1 1"/>
      </geometry>
    </collision>
    <visual>
      <origin rpy="0 0 0" xyz="0 0 0"/>
      <geometry>
        <mesh filename="package://raider_description/meshes/Left_shoulder.dae" scale="1 1 1"/>
      </geometry>
    </visual>
    <inertial>
        <origin xyz="0.0022520 0.0000026 0.0102760" rpy="0 0 0"/>
      <mass value="0.026"/>
        <inertia ixx="1.170649323e-2" ixy="-3.556832255e-7" ixz="1.401415789e-3" iyy="9.3521147e-3" iyz="1.884457751e-7" izz="1.450932481e-2"/>
    </inertial>
  </link>

  <joint name="left_shoulder_lateral" type="revolute">
    <dynamics damping="0.2" friction="1"/>
    <limit effort="3" lower="-2.618" upper="2.618" velocity="5.6"/>
    <parent link="left_shoulder"/>
    <child link="left_upper_arm"/>
    <origin rpy="0 0.0910695 0" xyz="0 0 0"/>
    <axis xyz="0 1 0"/>
  </joint>

  <link name="left_upper_arm">
    <collision>
      <origin rpy="0 0 0" xyz="0 0 0"/>
      <geometry>
        <mesh filename="package://raider_description/meshes/Left_upper_arm.stl" scale="1 1 1"/>
      </geometry>
    </collision>
    <visual>
      <origin rpy="0 0 0" xyz="0 0 0"/>
      <geometry>
        <mesh filename="package://raider_description/meshes/Left_upper_arm.dae" scale="1 1 1"/>
      </geometry>
    </visual>
    <inertial>
        <origin xyz="-0.0009873 -0.0008594 -0.0422507" rpy="0 0 0"/>
      <mass value="0.118"/>
        <inertia ixx="1.194654005e-1" ixy="-1.306061009e-5" ixz="-1.606455041e-3" iyy="1.194654005e-1" iyz="-1.606455041e-3" izz="1.922521805e-2"/>
    </inertial>
  </link>

    <joint name="left_elbow" type="revolute">
      <dynamics damping="0.2" friction="1"/>
      <limit lower="-2.618" upper="2.618" velocity="5.6" effort="3"/>
      <parent link="left_upper_arm"/>
      <child link="left_forearm"/>
      <origin xyz="-0.0032117 -0.0015761 -0.0838842" rpy="0 0 0"/>
      <axis xyz="1 0 0"/>
    </joint>

  <link name="left_forearm">
    <collision>
      <origin rpy="0 0 0" xyz="0 0 0"/>
      <geometry>
        <mesh filename="package://raider_description/meshes/Left_forearm.stl" scale="1 1 1"/>
      </geometry>
    </collision>
    <visual>
      <origin rpy="0 0 0" xyz="0 0 0"/>
      <geometry>
        <mesh filename="package://raider_description/meshes/Left_forearm.dae" scale="1 1 1"/>
      </geometry>
    </visual>
    <inertial>
        <origin xyz="-0.00116503 0.00375051 -0.02277706" rpy="0 0 0"/>
      <mass value="0.029"/>
        <inertia ixx="1.318173536e-2" ixy="3.27552493e-4" ixz="1.072368113e-3" iyy="1.793564679e-2" iyz="-6.665475568e-4" izz="1.169215698e-2"/>
    </inertial>
  </link>


  <joint name="left_forearm_sharp_joint" type="fixed">
    <parent link="left_forearm"/>
    <child link="left_sharp"/>
    <origin xyz="-0.00109569 -0.0104161 -0.0467332" rpy="0 0 -1.570796327"/>
  </joint>

  <link name="left_sharp">
    <collision>
      <origin rpy="0 0 0" xyz="0 0 0"/>
      <geometry>
        <mesh filename="package://raider_description/meshes/Left_sharp.stl" scale="1 1 1"/>
      </geometry>
    </collision>
    <visual>
      <origin rpy="0 0 0" xyz="0 0 0"/>
      <geometry>
        <mesh filename="package://raider_description/meshes/Left_sharp.dae" scale="1 1 1"/>
      </geometry>
    </visual>
    <inertial>
        <origin xyz="-0.00570060 0.00026204 0.00358805" rpy="0 0 0"/>
      <mass value="0.0035"/>
        <inertia ixx="3.385597579e-4" ixy="-9.036400778e-6" ixz="-7.205861856e-6" iyy="8.286926246e-5" iyz="6.067968112e-6" izz="3.272700008e-4"/>
    </inertial>
  </link>

  <joint name="left_forearm_hand_joint" type="fixed">
    <parent link="left_forearm"/>
    <child link="left_hand"/>
    <origin rpy="0 0 0" xyz="0.0018466 0.00426269 -0.0852268"/>
  </joint>

  <link name="left_hand">
    <collision>
      <origin rpy="0 0 0" xyz="0 0 0"/>
      <geometry>
        <mesh filename="package://raider_description/meshes/Left_hand.stl" scale="1 1 1"/>
      </geometry>
    </collision>
    <visual>
      <origin rpy="0 0 0" xyz="0 0 0"/>
      <geometry>
        <mesh filename="package://raider_description/meshes/Left_hand.dae" scale="1 1 1"/>
      </geometry>
    </visual>
    <inertial>
        <origin xyz="0.000000 0.0000056 0.0002176" rpy="0 0 0"/>
      <mass value="0.034"/>
        <inertia ixx="1.389915799e-2" ixy="0" ixz="0" iyy="1.311145434e-2" iyz="-1.863384983e-4" izz="5.945892083e-3"/>
    </inertial>
  </link>

  <joint name="right_shoulder_swing" type="revolute">
    <dynamics damping="0.2" friction="1"/>
    <limit effort="3" lower="-2.618" upper="2.618" velocity="5.6"/>
    <parent link="chest"/>
    <child link="right_shoulder"/>
    <origin xyz="0.0748183 -0.00030104 0.0092405"/>
    <axis xyz="1 0 0"/>
  </joint>

  <link name="right_shoulder">
    <collision>
      <origin rpy="0 0 0" xyz="0 0 0"/>
      <geometry>
        <mesh filename="package://raider_description/meshes/Right_shoulder.stl" scale="1 1 1"/>
      </geometry>
    </collision>
    <visual>
      <origin rpy="0 0 0" xyz="0 0 0"/>
      <geometry>
        <mesh filename="package://raider_description/meshes/Right_shoulder.dae" scale="1 1 1"/>
      </geometry>
    </visual>
    <inertial>
        <origin xyz="-0.0022520 0.0000026 0.0102760" rpy="0 0 0"/>
      <mass value="0.026"/>
        <inertia ixx="1.170649323e-2" ixy="3.556832255e-7" ixz="-1.401415789e-3" iyy="9.3521147e-3" iyz="1.884457751e-7" izz="1.450932481e-2"/>
    </inertial>
  </link>

  <joint name="right_shoulder_lateral" type="revolute">
    <dynamics damping="0.2" friction="1"/>
    <limit effort="3" lower="-2.618" upper="2.618" velocity="5.6"/>
    <parent link="right_shoulder"/>
    <child link="right_upper_arm"/>
    <origin rpy="0 0.0910695 3.14159265359" xyz="0 0 0"/>
    <axis xyz="0 1 0"/>
  </joint>

  <link name="right_upper_arm">
    <collision>
      <origin rpy="0 0 0" xyz="0 0 0"/>
      <geometry>
        <mesh filename="package://raider_description/meshes/Right_upper_arm.stl" scale="1 1 1"/>
      </geometry>
    </collision>
    <visual>
      <origin rpy="0 0 0" xyz="0 0 0"/>
      <geometry>
        <mesh filename="package://raider_description/meshes/Right_upper_arm.dae" scale="1 1 1"/>
      </geometry>
    </visual>
    <inertial>
        <origin xyz="-0.0009873 0.0008594 -0.0422507" rpy="0 0 0"/>
      <mass value="0.118"/>
        <inertia ixx="1.194654005e-1" ixy="1.306061009e-5" ixz="-1.606455041e-3" iyy="1.194654005e-1" iyz="1.606455041e-3" izz="1.922521805e-2"/>
    </inertial>
  </link>

    <joint name="right_elbow" type="revolute">
      <dynamics damping="0.2" friction="1"/>
      <limit lower="-2.618" upper="2.618" velocity="5.6" effort="3"/>
      <parent link="right_upper_arm"/>
      <child link="right_forearm"/>
      <origin xyz="-0.0032117 -0.0015761 -0.0838842" rpy="0 0 -3.14159265359"/>
      <axis xyz="1 0 0"/>
    </joint>

  <link name="right_forearm">
    <collision>
      <origin rpy="0 0 0" xyz="0 0 0"/>
      <geometry>
        <mesh filename="package://raider_description/meshes/Right_forearm.stl" scale="1 1 1"/>
      </geometry>
    </collision>
    <visual>
      <origin rpy="0 0 0" xyz="0 0 0"/>
      <geometry>
        <mesh filename="package://raider_description/meshes/Right_forearm.dae" scale="1 1 1"/>
      </geometry>
    </visual>
    <inertial>
        <origin xyz="0.00116503 0.00375051 -0.02277706" rpy="0 0 0"/>
      <mass value="0.029"/>
        <inertia ixx="1.318173536e-2" ixy="-3.27552493e-4" ixz="-1.072368113e-3" iyy="1.793564679e-2" iyz="-6.665475568e-4" izz="1.169215698e-2"/>
    </inertial>
  </link>

  <joint name="right_forearm_sharp_joint" type="fixed">
    <parent link="right_forearm"/>
    <child link="right_sharp"/>
    <origin xyz="0.00109569 -0.0104161 -0.0467332" rpy="0 0 -1.570796327"/>
  </joint>

  <link name="right_sharp">
    <collision>
      <origin rpy="0 0 0" xyz="0 0 0"/>
      <geometry>
        <mesh filename="package://raider_description/meshes/Right_sharp.stl" scale="1 1 1"/>
      </geometry>
    </collision>
    <visual>
      <origin rpy="0 0 0" xyz="0 0 0"/>
      <geometry>
        <mesh filename="package://raider_description/meshes/Right_sharp.dae" scale="1 1 1"/>
      </geometry>
    </visual>
    <inertial>
        <origin xyz="-0.00570060 -0.00026204 0.00358805" rpy="0 0 0"/>
      <mass value="0.0035"/>
        <inertia ixx="3.385597579e-4" ixy="-9.036400778e-6" ixz="-7.205861856e-6" iyy="8.286926246e-5" iyz="6.067968112e-6" izz="3.272700008e-4"/>
    </inertial>
  </link>

  <joint name="right_forearm_hand_joint" type="fixed">
    <parent link="right_forearm"/>
    <child link="right_hand"/>
    <origin rpy="0 0 0" xyz="-0.0018466 0.00426269 -0.0852268"/>
  </joint>

  <link name="right_hand">
    <collision>
      <origin rpy="0 0 0" xyz="0 0 0"/>
      <geometry>
        <mesh filename="package://raider_description/meshes/Right_hand.stl" scale="1 1 1"/>
      </geometry>
    </collision>
    <visual>
      <origin rpy="0 0 0" xyz="0 0 0"/>
      <geometry>
        <mesh filename="package://raider_description/meshes/Right_hand.dae" scale="1 1 1"/>
      </geometry>
    </visual>
    <inertial>
        <origin xyz="0.000000 0.0000056 0.0002176" rpy="0 0 0"/>
      <mass value="0.034"/>
        <inertia ixx="1.389915799e-2" ixy="0" ixz="0" iyy="1.311145434e-2" iyz="-1.863384983e-4" izz="5.945892083e-3"/>
    </inertial>
  </link>

  <joint name="left_hip_twist" type="revolute">
    <dynamics damping="0.2" friction="1"/>
    <limit effort="3" lower="-2.618" upper="2.618" velocity="5.6"/>
    <parent link="hip"/>
    <child link="left_leg_bracket"/>
    <origin rpy="0 0 0" xyz="-0.032 -0.0101551 -0.0186144"/>
    <axis xyz="0 0 1"/>
  </joint>

  <link name="left_leg_bracket">
    <collision>
      <origin rpy="0 0 0" xyz="0 0 0"/>
      <geometry>
        <mesh filename="package://raider_description/meshes/Left_leg_bracket.stl" scale="1 1 1"/>
      </geometry>
    </collision>
    <visual>
      <origin rpy="0 0 0" xyz="0 0 0"/>
      <geometry>
        <mesh filename="package://raider_description/meshes/Left_leg_bracket.dae" scale="1 1 1"/>
      </geometry>
    </visual>
    <inertial>
        <origin xyz="0.0005309 -0.0017209 -0.0083455" rpy="0 0 0"/>
      <mass value="0.017"/>
        <inertia ixx="1.49618601e-2" ixy="-2.325214372e-4" ixz="-8.04881898e-5" iyy="2.826029775e-3" iyz="-2.826029775e-4" izz="1.49708033e-2"/>
    </inertial>
  </link>

  <joint name="left_hip_lateral" type="revolute">
    <dynamics damping="0.2" friction="1"/>
    <limit effort="3" lower="-2.618" upper="2.618" velocity="5.6"/>
    <origin rpy="0 0 0" xyz="0.0000488 -0.017192 -0.02701342"/>
    <parent link="left_leg_bracket"/>
    <child link="left_upper_leg_servos"/>
    <axis xyz="0 1 0"/>
  </joint>

  <link name="left_upper_leg_servos">
    <collision>
      <origin rpy="0 0 0" xyz="0 0 0"/>
      <geometry>
        <mesh filename="package://raider_description/meshes/Left_upper_leg_servos.stl" scale="1 1 1"/>
      </geometry>
    </collision>
    <visual>
      <origin rpy="0 0 0" xyz="0 0 0"/>
      <geometry>
        <mesh filename="package://raider_description/meshes/Left_upper_leg_servos.dae" scale="1 1 1"/>
      </geometry>
    </visual>
    <inertial>
        <origin xyz="-0.0005065 0.0183145 -0.0132071" rpy="0 0 0"/>
      <mass value="0.127"/>
        <inertia ixx="7.259116708e-2" ixy="9.254754647e-4" ixz="1.433835227e-4" iyy="3.430776652e-2" iyz="2.476624483e-4" izz="6.234576264e-2"/>
    </inertial>
  </link>

  <joint name="left_hip_swing" type="revolute">
    <dynamics damping="0.2" friction="1"/>
    <limit effort="3" lower="-2.618" upper="2.618" velocity="5.6"/>
    <origin rpy="0 0 0" xyz="0 0.0342807 -0.00009354"/>
    <parent link="left_upper_leg_servos"/>
    <child link="left_upper_leg"/>
  </joint>

  <link name="left_upper_leg">
    <collision>
      <origin rpy="0 0 0" xyz="0 0 0"/>
      <geometry>
        <mesh filename="package://raider_description/meshes/Left_upper_leg.stl" scale="1 1 1"/>
      </geometry>
    </collision>
    <visual>
      <origin rpy="0 0 0" xyz="0 0 0"/>
      <geometry>
        <mesh filename="package://raider_description/meshes/Left_upper_leg.dae" scale="1 1 1"/>
      </geometry>
    </visual>
    <inertial>
        <origin xyz="-0.0014297 0.0037925 -0.0421587" rpy="0 0 0"/>
      <mass value="0.023"/>
        <inertia ixx="1.628504224e-2" ixy="-4.416282642e-5" ixz="4.416282642e-5" iyy="2.478638633e-2" iyz="1.258640553e-3" izz="1.216685868e-2"/>
    </inertial>
  </link>

  <joint name="left_upper_knee" type="revolute">
    <dynamics damping="0.2" friction="1"/>
    <origin rpy="0 0 0" xyz="0 0 -0.07456994"/>
    <limit effort="3" lower="-2.618" upper="2.618" velocity="5.6"/>
    <parent link="left_upper_leg"/>
    <child link="left_knee_servos"/>
  </joint>

  <link name="left_knee_servos">
    <collision>
      <origin rpy="0 0 0" xyz="0 0 0"/>
      <geometry>
        <mesh filename="package://raider_description/meshes/Left_knee_servos.stl" scale="1 1 1"/>
      </geometry>
    </collision>
    <visual>
      <origin rpy="0 0 0" xyz="0 0 0"/>
      <geometry>
        <mesh filename="package://raider_description/meshes/Left_knee_servos.dae" scale="1 1 1"/>
      </geometry>
    </visual>
    <inertial>
        <origin xyz="-0.0009309 -0.0138692 -0.0166406" rpy="0 0 0"/>
      <mass value="0.114"/>
        <inertia ixx="5.673983625e-2" ixy="8.18040655e-4" ixz="-6.571146245e-4" iyy="4.728543196e-2" iyz="1.166713721e-3" izz="3.465273857e-2"/>
    </inertial>
  </link>

  <joint name="left_lower_knee" type="fixed">
    <origin rpy="0 0 0" xyz="0 0 -0.0323448"/>
    <parent link="left_knee_servos"/>
    <child link="left_lower_leg"/>
  </joint>

  <link name="left_lower_leg">
    <collision>
      <origin rpy="0 0 0" xyz="0 0 0"/>
      <geometry>
        <mesh filename="package://raider_description/meshes/Left_lower_leg.stl" scale="1 1 1"/>
      </geometry>
    </collision>
    <visual>
      <origin rpy="0 0 0" xyz="0 0 0"/>
      <geometry>
        <mesh filename="package://raider_description/meshes/Left_lower_leg.dae" scale="1 1 1"/>
      </geometry>
    </visual>
    <inertial>
        <origin xyz="-0.0017136 0.0135252 -0.0273576" rpy="0 0 0"/>
      <mass value="0.044"/>
        <inertia ixx="4.046773335e-2" ixy="-7.641188321e-4" ixz="-9.067543474e-4" iyy="4.93722648e-2" iyz="-3.270428601e-3" izz="2.491027393e-2"/>
    </inertial>
  </link>

  <joint name="left_ankle_swing" type="revolute">
    <dynamics damping="0.2" friction="1"/>
    <limit effort="3" lower="-2.618" upper="2.618" velocity="5.6"/>
    <origin rpy="0 0 0" xyz="0 0 -0.0749237"/>
    <parent link="left_lower_leg"/>
    <child link="left_foot_servos"/>
    <axis xyz="1 0 0"/>
  </joint>

  <link name="left_foot_servos">
    <collision>
      <origin rpy="0 0 0" xyz="0 0 0"/>
      <geometry>
        <mesh filename="package://raider_description/meshes/Left_foot_servos.stl" scale="1 1 1"/>
      </geometry>
    </collision>
    <visual>
      <origin rpy="0 0 0" xyz="0 0 0"/>
      <geometry>
        <mesh filename="package://raider_description/meshes/Left_foot_servos.dae" scale="1 1 1"/>
      </geometry>
    </visual>
    <inertial>
        <origin xyz="-0.0005265 -0.0184132 0.0132893" rpy="0 0 0"/>
      <mass value="0.122"/>
        <inertia ixx="8.610423914e-2" ixy="1.07417429e-3" ixz="-1.440965511e-4" iyy="3.273611648e-2" iyz="-1.571962376e-4" izz="7.41442254e-2"/>
    </inertial>
  </link>

  <joint name="left_ankle_lateral" type="revolute">
    <dynamics damping="0.2" friction="1"/>
    <limit effort="3" lower="-2.618" upper="2.618" velocity="5.6"/>
    <parent link="left_foot_servos"/>
    <child link="left_foot"/>
    <origin rpy="0 0 0.0" xyz="0 0 0"/>
    <axis xyz="0 1 0"/>
  </joint>

  <link name="left_foot">
    <collision>
      <origin rpy="0 0 0" xyz="0 0 0"/>
      <geometry>
        <mesh filename="package://raider_description/meshes/Left_foot.stl" scale="1 1 1"/>
      </geometry>
    </collision>
    <visual>
      <origin rpy="0 0 0" xyz="0 0 0"/>
      <geometry>
        <mesh filename="package://raider_description/meshes/Left_foot.dae" scale="1 1 1"/>
      </geometry>
    </visual>
    <inertial>
        <origin xyz=" -0.0022669 0.0012954 -0.0218289" rpy="0 0 0"/>
      <mass value="0.031"/>
        <inertia ixx="2.227090747e-2" ixy="3.447508897e-5" ixz="-2.930382562e-4" iyy="8.360209075e-3" iyz="1.896129893e-4" izz="2.670957518e-2"/>
    </inertial>
  </link>

  <joint name="right_hip_twist" type="revolute">
    <dynamics damping="0.2" friction="1"/>
    <limit effort="3" lower="-2.618" upper="2.618" velocity="5.6"/>
    <parent link="hip"/>
    <child link="right_leg_bracket"/>
    <origin rpy="0 3.14159265359 0" xyz="0.032 -0.0101551 -0.0186144"/>
    <axis xyz="0 0 1"/>
  </joint>

  <link name="right_leg_bracket">
    <collision>
      <origin rpy="0 0 0" xyz="0 0 0"/>
      <geometry>
        <mesh filename="package://raider_description/meshes/Right_leg_bracket.stl" scale="1 1 1"/>
      </geometry>
    </collision>
    <visual>
      <origin rpy="0 0 0" xyz="0 0 0"/>
      <geometry>
        <mesh filename="package://raider_description/meshes/Right_leg_bracket.dae" scale="1 1 1"/>
      </geometry>
    </visual>
    <inertial>
        <origin xyz="0.0005309 -0.0017209 0.0083455" rpy="0 0 0"/>
      <mass value="0.017"/>
        <inertia ixx="1.49618601e-2" ixy="-2.325214372e-4" ixz="8.04881898e-5" iyy="2.826029775e-3" iyz="2.826029775e-4" izz="1.49708033e-2"/>
    </inertial>
  </link>

  <joint name="right_hip_lateral" type="revolute">
    <dynamics damping="0.2" friction="1"/>
    <limit effort="3" lower="-2.618" upper="2.618" velocity="5.6"/>
    <origin rpy="0 -3.14159265359 3.14159265359" xyz="0.0000488 -0.017192 0.02701342"/>
    <parent link="right_leg_bracket"/>
    <child link="right_upper_leg_servos"/>
    <axis xyz="0 1 0"/>
  </joint>

  <link name="right_upper_leg_servos">
    <collision>
      <origin rpy="0 0 0" xyz="0 0 0"/>
      <geometry>
        <mesh filename="package://raider_description/meshes/Right_upper_leg_servos.stl" scale="1 1 1"/>
      </geometry>
    </collision>
    <visual>
      <origin rpy="0 0 0" xyz="0 0 0"/>
      <geometry>
        <mesh filename="package://raider_description/meshes/Right_upper_leg_servos.dae" scale="1 1 1"/>
      </geometry>
    </visual>
    <inertial>
        <origin xyz="-0.0005065 -0.0183145 -0.0132071" rpy="0 0 0"/>
      <mass value="0.127"/>
        <inertia ixx="7.259116708e-2" ixy="-9.254754647e-4" ixz="1.433835227e-4" iyy="3.430776652e-2" iyz="-2.476624483e-4" izz="6.234576264e-2"/>
    </inertial>
  </link>

  <joint name="right_hip_swing" type="revolute">
    <dynamics damping="0.2" friction="1"/>
    <limit effort="3" lower="-2.618" upper="2.618" velocity="5.6"/>
    <origin rpy="0 0 -3.14159265359" xyz="0 -0.0342807 -0.00009354"/>
    <parent link="right_upper_leg_servos"/>
    <child link="right_upper_leg"/>
  </joint>

  <link name="right_upper_leg">
    <collision>
      <origin rpy="0 0 0" xyz="0 0 0"/>
      <geometry>
        <mesh filename="package://raider_description/meshes/Right_upper_leg.stl" scale="1 1 1"/>
      </geometry>
    </collision>
    <visual>
      <origin rpy="0 0 0" xyz="0 0 0"/>
      <geometry>
        <mesh filename="package://raider_description/meshes/Right_upper_leg.dae" scale="1 1 1"/>
      </geometry>
    </visual>
    <inertial>
        <origin xyz="0.0014297 0.0037925 -0.0421587" rpy="0 0 0"/>
      <mass value="0.023"/>
        <inertia ixx="1.628504224e-2" ixy="4.416282642e-5" ixz="-4.416282642e-5" iyy="2.478638633e-2" iyz="1.258640553e-3" izz="1.216685868e-2"/>
    </inertial>
  </link>

  <joint name="right_upper_knee" type="revolute">
    <dynamics damping="0.2" friction="1"/>
    <origin rpy="0 0 0" xyz="0 0 -0.07456994"/>
    <limit effort="3" lower="-2.618" upper="2.618" velocity="5.6"/>
    <parent link="right_upper_leg"/>
    <child link="right_knee_servos"/>
  </joint>

  <link name="right_knee_servos">
    <collision>
      <origin rpy="0 0 0" xyz="0 0 0"/>
      <geometry>
        <mesh filename="package://raider_description/meshes/Right_knee_servos.stl" scale="1 1 1"/>
      </geometry>
    </collision>
    <visual>
      <origin rpy="0 0 0" xyz="0 0 0"/>
      <geometry>
        <mesh filename="package://raider_description/meshes/Right_knee_servos.dae" scale="1 1 1"/>
      </geometry>
    </visual>
    <inertial>
        <origin xyz="0.0009309 -0.0138692 -0.0166406" rpy="0 0 0"/>
      <mass value="0.114"/>
        <inertia ixx="5.673983625e-2" ixy="-8.18040655e-4" ixz="6.571146245e-4" iyy="4.728543196e-2" iyz="1.166713721e-3" izz="3.465273857e-2"/>
    </inertial>
  </link>

  <joint name="right_lower_knee" type="fixed">
    <origin rpy="0 0 0" xyz="0 0 -0.0323448"/>
    <parent link="right_knee_servos"/>
    <child link="right_lower_leg"/>
  </joint>

  <link name="right_lower_leg">
    <collision>
      <origin rpy="0 0 0" xyz="0 0 0"/>
      <geometry>
        <mesh filename="package://raider_description/meshes/Right_lower_leg.stl" scale="1 1 1"/>
      </geometry>
    </collision>
    <visual>
      <origin rpy="0 0 0" xyz="0 0 0"/>
      <geometry>
        <mesh filename="package://raider_description/meshes/Right_lower_leg.dae" scale="1 1 1"/>
      </geometry>
    </visual>
    <inertial>
        <origin xyz="0.0017136 0.0135252 -0.0273576" rpy="0 0 0"/>
      <mass value="0.044"/>
        <inertia ixx="4.046773335e-2" ixy="7.641188321e-4" ixz="9.067543474e-4" iyy="4.93722648e-2" iyz="-3.270428601e-3" izz="2.491027393e-2"/>
    </inertial>
  </link>

  <joint name="right_ankle_swing" type="revolute">
    <dynamics damping="0.2" friction="1"/>
    <limit effort="3" lower="-2.618" upper="2.618" velocity="5.6"/>
    <origin rpy="0 0 0" xyz="0 0 -0.0749237"/>
    <parent link="right_lower_leg"/>
    <child link="right_foot_servos"/>
    <axis xyz="1 0 0"/>
  </joint>

  <link name="right_foot_servos">
    <collision>
      <origin rpy="0 0 0" xyz="0 0 0"/>
      <geometry>
        <mesh filename="package://raider_description/meshes/Right_foot_servos.stl" scale="1 1 1"/>
      </geometry>
    </collision>
    <visual>
      <origin rpy="0 0 0" xyz="0 0 0"/>
      <geometry>
        <mesh filename="package://raider_description/meshes/Right_foot_servos.dae" scale="1 1 1"/>
      </geometry>
    </visual>
    <inertial>
        <origin xyz="0.0005265 -0.0184132 0.0132893" rpy="0 0 0"/>
      <mass value="0.122"/>
        <inertia ixx="8.610423914e-2" ixy="-1.07417429e-3" ixz="1.440965511e-4" iyy="3.273611648e-2" iyz="-1.571962376e-4" izz="7.41442254e-2"/>
    </inertial>
  </link>

  <joint name="right_ankle_lateral" type="revolute">
    <dynamics damping="0.2" friction="1"/>
    <limit effort="3" lower="-2.618" upper="2.618" velocity="5.6"/>
    <parent link="right_foot_servos"/>
    <child link="right_foot"/>
    <origin rpy="0 0 3.14159265359" xyz="0 0 0"/>
    <axis xyz="0 1 0"/>
  </joint>

  <link name="right_foot">
    <collision>
      <origin rpy="0 0 0" xyz="0 0 0"/>
      <geometry>
        <mesh filename="package://raider_description/meshes/Right_foot.stl" scale="1 1 1"/>
      </geometry>
    </collision>
    <visual>
      <origin rpy="0 0 0" xyz="0 0 0"/>
      <geometry>
        <mesh filename="package://raider_description/meshes/Right_foot.dae" scale="1 1 1"/>
      </geometry>
    </visual>
    <inertial>
        <origin xyz=" -0.0022669 -0.0012954 -0.0218289" rpy="0 0 0"/>
      <mass value="0.031"/>
        <inertia ixx="2.227090747e-2" ixy="-3.447508897e-5" ixz="-2.930382562e-4" iyy="8.360209075e-3" iyz="-1.896129893e-4" izz="2.670957518e-2"/>
    </inertial>
  </link>


<gazebo reference = "left_foot">
    <mu1>9000</mu1>
    <mu2>9000</mu2>
    <kp>1000000.0</kp>
    <kd>10.0</kd>
    <minDepth>0.001</minDepth>
    <maxContacts>1</maxContacts>
</gazebo>


<gazebo reference = "right_foot">
    <mu1>9000</mu1>
    <mu2>9000</mu2>
    <kp>1000000.0</kp>
    <kd>10.0</kd>
    <minDepth>0.001</minDepth>
    <maxContacts>1</maxContacts>
</gazebo>


  <!-- Import gazebo_ros_control plugin -->
  <gazebo>
    <plugin filename="libgazebo_ros_control.so" name="gazebo_ros_control_raider">
      <robotNamespace>/raider</robotNamespace>
      <robotSimType>gazebo_ros_control/DefaultRobotHWSim</robotSimType>
    </plugin>
  </gazebo>

  <transmission name="middle_hip_twist_tran">
    <type>transmission_interface/SimpleTransmission</type>
    <joint name="middle_hip_twist">
      <hardwareInterface>PosVelJointInterface</hardwareInterface>
    </joint>
    <actuator name="middle_hip_twist_motor">
      <hardwareInterface>PosVelJointInterface</hardwareInterface>
      <mechanicalReduction>1</mechanicalReduction>
    </actuator>
  </transmission>

  <transmission name="neck_tran">
    <type>transmission_interface/SimpleTransmission</type>
    <joint name="neck">
      <hardwareInterface>PosVelJointInterface</hardwareInterface>
    </joint>
    <actuator name="neck_motor">
      <hardwareInterface>PosVelJointInterface</hardwareInterface>
      <mechanicalReduction>1</mechanicalReduction>
    </actuator>
  </transmission>

  <transmission name="right_shoulder_swing_tran">
    <type>transmission_interface/SimpleTransmission</type>
    <joint name="right_shoulder_swing">
      <hardwareInterface>PosVelJointInterface</hardwareInterface>
    </joint>
    <actuator name="right_shoulder_swing_motor">
      <hardwareInterface>PosVelJointInterface</hardwareInterface>
      <mechanicalReduction>1</mechanicalReduction>
    </actuator>
  </transmission>
  <transmission name="left_shoulder_swing_tran">
    <type>transmission_interface/SimpleTransmission</type>
    <joint name="left_shoulder_swing">
      <hardwareInterface>PosVelJointInterface</hardwareInterface>
    </joint>
    <actuator name="left_shoulder_swing_motor">
      <hardwareInterface>PosVelJointInterface</hardwareInterface>
      <mechanicalReduction>1</mechanicalReduction>
    </actuator>
  </transmission>
  <transmission name="right_shoulder_lateral_tran">
    <type>transmission_interface/SimpleTransmission</type>
    <joint name="right_shoulder_lateral">
      <hardwareInterface>PosVelJointInterface</hardwareInterface>
    </joint>
    <actuator name="right_shoulder_lateral_motor">
      <hardwareInterface>PosVelJointInterface</hardwareInterface>
      <mechanicalReduction>1</mechanicalReduction>
    </actuator>
  </transmission>
  <transmission name="left_shoulder_lateral_tran">
    <type>transmission_interface/SimpleTransmission</type>
    <joint name="left_shoulder_lateral">
      <hardwareInterface>PosVelJointInterface</hardwareInterface>
    </joint>
    <actuator name="left_shoulder_lateral_motor">
      <hardwareInterface>PosVelJointInterface</hardwareInterface>
      <mechanicalReduction>1</mechanicalReduction>
    </actuator>
  </transmission>
  <transmission name="right_elbow_tran">
    <type>transmission_interface/SimpleTransmission</type>
    <joint name="right_elbow">
      <hardwareInterface>PosVelJointInterface</hardwareInterface>
    </joint>
    <actuator name="right_elbow_motor">
      <hardwareInterface>PosVelJointInterface</hardwareInterface>
      <mechanicalReduction>1</mechanicalReduction>
    </actuator>
  </transmission>
  <transmission name="left_elbow_tran">
    <type>transmission_interface/SimpleTransmission</type>
    <joint name="left_elbow">
      <hardwareInterface>PosVelJointInterface</hardwareInterface>
    </joint>
    <actuator name="left_elbow_motor">
      <hardwareInterface>PosVelJointInterface</hardwareInterface>
      <mechanicalReduction>1</mechanicalReduction>
    </actuator>
  </transmission>
  <transmission name="right_hip_twist_tran">
    <type>transmission_interface/SimpleTransmission</type>
    <joint name="right_hip_twist">
      <hardwareInterface>PosVelJointInterface</hardwareInterface>
    </joint>
    <actuator name="right_hip_twist_motor">
      <hardwareInterface>PosVelJointInterface</hardwareInterface>
      <mechanicalReduction>1</mechanicalReduction>
    </actuator>
  </transmission>
  <transmission name="left_hip_twist_tran">
    <type>transmission_interface/SimpleTransmission</type>
    <joint name="left_hip_twist">
      <hardwareInterface>PosVelJointInterface</hardwareInterface>
    </joint>
    <actuator name="left_hip_twist_motor">
      <hardwareInterface>PosVelJointInterface</hardwareInterface>
      <mechanicalReduction>1</mechanicalReduction>
    </actuator>
  </transmission>
  <transmission name="right_hip_lateral_tran">
    <type>transmission_interface/SimpleTransmission</type>
    <joint name="right_hip_lateral">
      <hardwareInterface>PosVelJointInterface</hardwareInterface>
    </joint>
    <actuator name="right_hip_lateral_motor">
      <hardwareInterface>PosVelJointInterface</hardwareInterface>
      <mechanicalReduction>1</mechanicalReduction>
    </actuator>
  </transmission>
  <transmission name="left_hip_lateral_tran">
    <type>transmission_interface/SimpleTransmission</type>
    <joint name="left_hip_lateral">
      <hardwareInterface>PosVelJointInterface</hardwareInterface>
    </joint>
    <actuator name="left_hip_lateral_motor">
      <hardwareInterface>PosVelJointInterface</hardwareInterface>
      <mechanicalReduction>1</mechanicalReduction>
    </actuator>
  </transmission>
  <transmission name="right_hip_swing_tran">
    <type>transmission_interface/SimpleTransmission</type>
    <joint name="right_hip_swing">
      <hardwareInterface>PosVelJointInterface</hardwareInterface>
    </joint>
    <actuator name="right_hip_swing_motor">
      <hardwareInterface>PosVelJointInterface</hardwareInterface>
      <mechanicalReduction>1</mechanicalReduction>
    </actuator>
  </transmission>
  <transmission name="left_hip_swing_tran">
    <type>transmission_interface/SimpleTransmission</type>
    <joint name="left_hip_swing">
      <hardwareInterface>PosVelJointInterface</hardwareInterface>
    </joint>
    <actuator name="left_hip_swing_motor">
      <hardwareInterface>PosVelJointInterface</hardwareInterface>
      <mechanicalReduction>1</mechanicalReduction>
    </actuator>
  </transmission>
  <transmission name="right_upper_knee_tran">
    <type>transmission_interface/SimpleTransmission</type>
    <joint name="right_upper_knee">
      <hardwareInterface>PosVelJointInterface</hardwareInterface>
    </joint>
    <actuator name="right_upper_knee_motor">
      <hardwareInterface>PosVelJointInterface</hardwareInterface>
      <mechanicalReduction>1</mechanicalReduction>
    </actuator>
  </transmission>
  <transmission name="left_upper_knee_tran">
    <type>transmission_interface/SimpleTransmission</type>
    <joint name="left_upper_knee">
      <hardwareInterface>PosVelJointInterface</hardwareInterface>
    </joint>
    <actuator name="left_upper_knee_motor">
      <hardwareInterface>PosVelJointInterface</hardwareInterface>
      <mechanicalReduction>1</mechanicalReduction>
    </actuator>
  </transmission>
  <transmission name="right_ankle_swing_tran">
    <type>transmission_interface/SimpleTransmission</type>
    <joint name="right_ankle_swing">
      <hardwareInterface>PosVelJointInterface</hardwareInterface>
    </joint>
    <actuator name="right_ankle_swing_motor">
      <hardwareInterface>PosVelJointInterface</hardwareInterface>
      <mechanicalReduction>1</mechanicalReduction>
    </actuator>
  </transmission>
  <transmission name="left_ankle_swing_tran">
    <type>transmission_interface/SimpleTransmission</type>
    <joint name="left_ankle_swing">
      <hardwareInterface>PosVelJointInterface</hardwareInterface>
    </joint>
    <actuator name="left_ankle_swing_motor">
      <hardwareInterface>PosVelJointInterface</hardwareInterface>
      <mechanicalReduction>1</mechanicalReduction>
    </actuator>
  </transmission>
  <transmission name="right_ankle_lateral_tran">
    <type>transmission_interface/SimpleTransmission</type>
    <joint name="right_ankle_lateral">
      <hardwareInterface>PosVelJointInterface</hardwareInterface>
    </joint>
    <actuator name="right_ankle_lateral_motor">
      <hardwareInterface>PosVelJointInterface</hardwareInterface>
      <mechanicalReduction>1</mechanicalReduction>
    </actuator>
  </transmission>
  <transmission name="left_ankle_lateral_tran">
    <type>transmission_interface/SimpleTransmission</type>
    <joint name="left_ankle_lateral">
      <hardwareInterface>PosVelJointInterface</hardwareInterface>
    </joint>
    <actuator name="left_ankle_lateral_motor">
      <hardwareInterface>PosVelJointInterface</hardwareInterface>
      <mechanicalReduction>1</mechanicalReduction>
    </actuator>
  </transmission>


<!-- LifeCam plugin -->
<gazebo reference="lifecam">
    <sensor type="camera" name="camera1">
      <update_rate>30.0</update_rate>
      <camera name="lifecam">
        <horizontal_fov>1.27409</horizontal_fov>
        <image>
          <width>1280</width>
          <height>720</height>
          <format>R8G8B8</format>
        </image>
        <clip>
          <near>0.001</near>
          <far>3</far>
        </clip>
        <noise>
          <type>gaussian</type>
          <!-- Noise is sampled independently per pixel on each frame.
               That pixel's noise value is added to each of its color
               channels, which at that point lie in the range [0,1]. -->
          <mean>0.0</mean>
          <stddev>0.007</stddev>
        </noise>
      </camera>
      <plugin name="camera_controller" filename="libgazebo_ros_camera.so">
        <alwaysOn>true</alwaysOn>
        <updateRate>30.0</updateRate>
        <cameraName>raider/lifecam</cameraName>
        <imageTopicName>image_raw</imageTopicName>
        <cameraInfoTopicName>camera_info</cameraInfoTopicName>
        <frameName>lifecam</frameName>
        <hackBaseline>0.07</hackBaseline>
        <distortionK1>0.0</distortionK1>
        <distortionK2>0.0</distortionK2>
        <distortionK3>0.0</distortionK3>
        <distortionT1>0.0</distortionT1>
        <distortionT2>0.0</distortionT2>
      </plugin>
    </sensor>
  </gazebo>

  <!--Sonar plugin-->
  <gazebo reference="ultrasonic">
      <sensor type="ray" name="sonar">
          <pose>0 0 0 0 0 0</pose>
          <update_rate>5</update_rate>
           <visualize>false</visualize>
          <ray>
            <scan>
              <horizontal>
                <samples>5</samples>
                <resolution>1.0</resolution>
                <min_angle>-0.2617993878</min_angle>
                <max_angle>0.2617993878</max_angle>
              </horizontal>
              <vertical>
                <samples>5</samples>
                <resolution>1.0</resolution>
                <min_angle>-0.2617993878</min_angle>
                <max_angle>0.2617993878</max_angle>
              </vertical>
            </scan>
            <range>
              <min>0.02</min>
              <max>4</max>
              <resolution>0.003</resolution>
            </range>
          </ray>
          <plugin filename="libgazebo_ros_range.so" name="gazebo_ros_range">
            <gaussianNoise>0.005</gaussianNoise>
            <alwaysOn>true</alwaysOn>
            <updateRate>5</updateRate>
            <topicName>sonar</topicName>
            <frameName>ultrasonic</frameName>
            <fov>0.5</fov>
            <radiation>ultrasound</radiation>
          </plugin>
      </sensor>
  </gazebo>

  <gazebo reference="left_sharp">
      <sensor type="ray" name="left_sharp">
          <pose>0 0 0 0 0 0</pose>
          <update_rate>5</update_rate>
           <visualize>false</visualize>
          <ray>
            <range>
              <min>0.02</min>
              <max>4</max>
              <resolution>0.003</resolution>
            </range>
          </ray>
          <plugin filename="libgazebo_ros_range.so" name="gazebo_ros_range_left_sharp">
            <gaussianNoise>0.005</gaussianNoise>
            <alwaysOn>true</alwaysOn>
            <updateRate>5</updateRate>
            <topicName>left_sharp</topicName>
            <frameName>left_sharp</frameName>
            <fov>0.5</fov>
            <radiation>infrared</radiation>
          </plugin>
      </sensor>
  </gazebo>

  <gazebo reference="right_sharp">
      <sensor type="ray" name="right_sharp">
          <pose>0 0 0 0 0 0</pose>
          <update_rate>5</update_rate>
           <visualize>false</visualize>
          <ray>
            <range>
              <min>0.02</min>
              <max>4</max>
              <resolution>0.003</resolution>
            </range>
          </ray>
          <plugin filename="libgazebo_ros_range.so" name="gazebo_ros_range_right_sharp">
            <gaussianNoise>0.005</gaussianNoise>
            <alwaysOn>true</alwaysOn>
            <updateRate>5</updateRate>
            <topicName>right_sharp</topicName>
            <frameName>right_sharp</frameName>
            <fov>0.5</fov>
            <radiation>infrared</radiation>
          </plugin>
      </sensor>
  </gazebo>

</robot>
